Workbook
Name scoreA1: 'NE PAS TOUCHER Calcul'!$B$11
Name scoreB1: 'NE PAS TOUCHER Calcul'!$C$11
Name scoreC: 'NE PAS TOUCHER Calcul'!$D$11
Name scoreC1: 'NE PAS TOUCHER Calcul'!$D$11

Sheet Résultats
A1: Mode d'emploi Cette feuille de calcul est destinée à aider à la fusion de listes aux élections municipales entre les deux tours. Elle calcule la répartition des places sur la liste fusionnée entre les listes de premier tour ayant décidé de fusionner entre elles. Elle utilise pour cela la méthode d'Hondt. Pour l'utiliser, il suffit de renseigner les cases en jaune (uniquement) en indiquant : - dans la colonne A, en dessous de « Liste », le nom des listes ayant accepté de fusionner (vous pouvez effacer les intitulés de liste en trop, mais sans supprimer les lignes) - dans la colonne B, en dessous de « Score du 1er tour (en voix OU en %) », le score réalisé par ces listes en voix (le plus précis) ou en pourcentage - dans la colonne E : - le sexe à l'état civil de la tête de liste fusionnée (du 2d tour) - le nombre de sièges au Conseil municipal de votre commune (sans les éventuels candidats supplémentaires, qui sont ajoutés automatiquement) - le nombre de sièges qui reviennent à votre commune au conseil communautaire (sans les +1 ou +2 candidatures supplémentaires obligatoires, qui sont ajoutées automatiquement) Les autres cases, colonnes et feuilles du tableau ne doivent pas être touchées. Vous obtenez automatiquement : - dans les colonnes G, H et I : une liste au Conseil municipal dont l'ordonnancement respecte la proportionnelle stricte selon les scores du premier tour. - dans les colonnes K, L et M : une liste au Conseil communautaire dont l'ordonnancement respecte la proportionnelle stricte selon les scores du premier tour.
A3: Liste | B3: Score du 1er tour (en voix OU en % avec le format XX,XX) | D3: Sexe à l'état civil de la tête de liste du 2d tour | E3: H | G3: Liste ordonnancée du 2e tour au Conseil municipal | K3: Liste ordonnancée du 2e tour au Conseil communautaire | O3: Récapitulatif par liste | P3: Nombre de candidat·es sur la liste fusionnée au Conseil municipal | Q3: Nombre de candidat·es sur la liste fusionnée au Conseil communautaire
A4: Liste 1 | B4: 19 | G4: # | H4: Liste T1 | I4: Sexe | K4: # | L4: Liste T1 | M4: Sexe | O4: {=A4:A20} -> Liste 1 | P4: =COUNTIF($H$4:$H$169,$O4) -> 20 | Q4: =COUNTIF($L$4:$L$64,$O4) -> 1
A5: Liste 2 | B5: 22 | D5: Nombre de sièges au Conseil municipal | E5: 43 | G5: 1 | H5: =IF(G5<>"",'NE PAS TOUCHER Calcul'!$BB17,"") -> Liste 2 | I5: =$E$3 -> H | K5: 1 | L5: =IF(K5<>"",'NE PAS TOUCHER Calcul'!$BB17,"") -> Liste 2 | M5: =$E$3 -> H | O5: Liste 2 | P5: =COUNTIF($H$4:$H$169,$O5) -> 23 | Q5: =COUNTIF($L$4:$L$64,$O5) -> 1
A6: Liste 3 | G6: =IF(G5<>"",IF(($G5+1)<=($E$5+2),G5+1,""),"") -> 2 | H6: =IF(G6<>"",'NE PAS TOUCHER Calcul'!$BB18,"") -> Liste 1 | I6: =IF(G6<>"",IF(I5="F","H","F"),"") -> F | K6: =IF(K5<>"",IF(K5+1<=IF($E$7<5,$E$7+1,$E$7+2),$K5+1,""),"") -> 2 | L6: =IF(K6<>"",'NE PAS TOUCHER Calcul'!$BB18,"") -> Liste 1 | M6: =IF(K6<>"",IF(M5="F","H","F"),"") -> F | O6: Liste 3 | P6: =COUNTIF($H$4:$H$169,$O6) -> 0 | Q6: =COUNTIF($L$4:$L$64,$O6) -> 0
A7: Liste 4 | D7: Nombre de sièges au Conseil communautaire | E7: 1 | G7: =IF(G6<>"",IF(($G6+1)<=($E$5+2),G6+1,""),"") -> 3 | H7: =IF(G7<>"",'NE PAS TOUCHER Calcul'!$BB19,"") -> Liste 2 | I7: =IF(G7<>"",IF(I6="F","H","F"),"") -> H | K7: =IF(K6<>"",IF(K6+1<=IF($E$7<5,$E$7+1,$E$7+2),$K6+1,""),"") | L7: =IF(K7<>"",'NE PAS TOUCHER Calcul'!$BB19,"") | M7: =IF(K7<>"",IF(M6="F","H","F"),"") | O7: Liste 4 | P7: =COUNTIF($H$4:$H$169,$O7) -> 0 | Q7: =COUNTIF($L$4:$L$64,$O7) -> 0
A8: Liste 5 | G8: =IF(G7<>"",IF(($G7+1)<=($E$5+2),G7+1,""),"") -> 4 | H8: =IF(G8<>"",'NE PAS TOUCHER Calcul'!$BB20,"") -> Liste 1 | I8: =IF(G8<>"",IF(I7="F","H","F"),"") -> F | K8: =IF(K7<>"",IF(K7+1<=IF($E$7<5,$E$7+1,$E$7+2),$K7+1,""),"") | L8: =IF(K8<>"",'NE PAS TOUCHER Calcul'!$BB20,"") | M8: =IF(K8<>"",IF(M7="F","H","F"),"") | O8: Liste 5 | P8: =COUNTIF($H$4:$H$169,$O8) -> 0 | Q8: =COUNTIF($L$4:$L$64,$O8) -> 0
A9: Liste 6 | G9: =IF(G8<>"",IF(($G8+1)<=($E$5+2),G8+1,""),"") -> 5 | H9: =IF(G9<>"",'NE PAS TOUCHER Calcul'!$BB21,"") -> Liste 2 | I9: =IF(G9<>"",IF(I8="F","H","F"),"") -> H | K9: =IF(K8<>"",IF(K8+1<=IF($E$7<5,$E$7+1,$E$7+2),$K8+1,""),"") | L9: =IF(K9<>"",'NE PAS TOUCHER Calcul'!$BB21,"") | M9: =IF(K9<>"",IF(M8="F","H","F"),"") | O9: Liste 6 | P9: =COUNTIF($H$4:$H$169,$O9) -> 0 | Q9: =COUNTIF($L$4:$L$64,$O9) -> 0
A10: Liste 7 | G10: =IF(G9<>"",IF(($G9+1)<=($E$5+2),G9+1,""),"") -> 6 | H10: =IF(G10<>"",'NE PAS TOUCHER Calcul'!$BB22,"") -> Liste 1 | I10: =IF(G10<>"",IF(I9="F","H","F"),"") -> F | K10: =IF(K9<>"",IF(K9+1<=IF($E$7<5,$E$7+1,$E$7+2),$K9+1,""),"") | L10: =IF(K10<>"",'NE PAS TOUCHER Calcul'!$BB22,"") | M10: =IF(K10<>"",IF(M9="F","H","F"),"") | O10: Liste 7 | P10: =COUNTIF($H$4:$H$169,$O10) -> 0 | Q10: =COUNTIF($L$4:$L$64,$O10) -> 0
A11: Liste 8 | G11: =IF(G10<>"",IF(($G10+1)<=($E$5+2),G10+1,""),"") -> 7 | H11: =IF(G11<>"",'NE PAS TOUCHER Calcul'!$BB23,"") -> Liste 2 | I11: =IF(G11<>"",IF(I10="F","H","F"),"") -> H | K11: =IF(K10<>"",IF(K10+1<=IF($E$7<5,$E$7+1,$E$7+2),$K10+1,""),"") | L11: =IF(K11<>"",'NE PAS TOUCHER Calcul'!$BB23,"") | M11: =IF(K11<>"",IF(M10="F","H","F"),"") | O11: Liste 8 | P11: =COUNTIF($H$4:$H$169,$O11) -> 0 | Q11: =COUNTIF($L$4:$L$64,$O11) -> 0
A12: Liste 9 | G12: =IF(G11<>"",IF(($G11+1)<=($E$5+2),G11+1,""),"") -> 8 | H12: =IF(G12<>"",'NE PAS TOUCHER Calcul'!$BB24,"") -> Liste 1 | I12: =IF(G12<>"",IF(I11="F","H","F"),"") -> F | K12: =IF(K11<>"",IF(K11+1<=IF($E$7<5,$E$7+1,$E$7+2),$K11+1,""),"") | L12: =IF(K12<>"",'NE PAS TOUCHER Calcul'!$BB24,"") | M12: =IF(K12<>"",IF(M11="F","H","F"),"") | O12: Liste 9 | P12: =COUNTIF($H$4:$H$169,$O12) -> 0 | Q12: =COUNTIF($L$4:$L$64,$O12) -> 0
A13: Liste 10 | G13: =IF(G12<>"",IF(($G12+1)<=($E$5+2),G12+1,""),"") -> 9 | H13: =IF(G13<>"",'NE PAS TOUCHER Calcul'!$BB25,"") -> Liste 2 | I13: =IF(G13<>"",IF(I12="F","H","F"),"") -> H | K13: =IF(K12<>"",IF(K12+1<=IF($E$7<5,$E$7+1,$E$7+2),$K12+1,""),"") | L13: =IF(K13<>"",'NE PAS TOUCHER Calcul'!$BB25,"") | M13: =IF(K13<>"",IF(M12="F","H","F"),"") | O13: Liste 10 | P13: =COUNTIF($H$4:$H$169,$O13) -> 0 | Q13: =COUNTIF($L$4:$L$64,$O13) -> 0
A14: Liste 11 | G14: =IF(G13<>"",IF(($G13+1)<=($E$5+2),G13+1,""),"") -> 10 | H14: =IF(G14<>"",'NE PAS TOUCHER Calcul'!$BB26,"") -> Liste 1 | I14: =IF(G14<>"",IF(I13="F","H","F"),"") -> F | K14: =IF(K13<>"",IF(K13+1<=IF($E$7<5,$E$7+1,$E$7+2),$K13+1,""),"") | L14: =IF(K14<>"",'NE PAS TOUCHER Calcul'!$BB26,"") | M14: =IF(K14<>"",IF(M13="F","H","F"),"") | O14: Liste 11 | P14: =COUNTIF($H$4:$H$169,$O14) -> 0 | Q14: =COUNTIF($L$4:$L$64,$O14) -> 0
A15: Liste 12 | G15: =IF(G14<>"",IF(($G14+1)<=($E$5+2),G14+1,""),"") -> 11 | H15: =IF(G15<>"",'NE PAS TOUCHER Calcul'!$BB27,"") -> Liste 2 | I15: =IF(G15<>"",IF(I14="F","H","F"),"") -> H | K15: =IF(K14<>"",IF(K14+1<=IF($E$7<5,$E$7+1,$E$7+2),$K14+1,""),"") | L15: =IF(K15<>"",'NE PAS TOUCHER Calcul'!$BB27,"") | M15: =IF(K15<>"",IF(M14="F","H","F"),"") | O15: Liste 12 | P15: =COUNTIF($H$4:$H$169,$O15) -> 0 | Q15: =COUNTIF($L$4:$L$64,$O15) -> 0
A16: Liste 13 | G16: =IF(G15<>"",IF(($G15+1)<=($E$5+2),G15+1,""),"") -> 12 | H16: =IF(G16<>"",'NE PAS TOUCHER Calcul'!$BB28,"") -> Liste 1 | I16: =IF(G16<>"",IF(I15="F","H","F"),"") -> F | K16: =IF(K15<>"",IF(K15+1<=IF($E$7<5,$E$7+1,$E$7+2),$K15+1,""),"") | L16: =IF(K16<>"",'NE PAS TOUCHER Calcul'!$BB28,"") | M16: =IF(K16<>"",IF(M15="F","H","F"),"") | O16: Liste 13 | P16: =COUNTIF($H$4:$H$169,$O16) -> 0 | Q16: =COUNTIF($L$4:$L$64,$O16) -> 0
A17: Liste 14 | G17: =IF(G16<>"",IF(($G16+1)<=($E$5+2),G16+1,""),"") -> 13 | H17: =IF(G17<>"",'NE PAS TOUCHER Calcul'!$BB29,"") -> Liste 2 | I17: =IF(G17<>"",IF(I16="F","H","F"),"") -> H | K17: =IF(K16<>"",IF(K16+1<=IF($E$7<5,$E$7+1,$E$7+2),$K16+1,""),"") | L17: =IF(K17<>"",'NE PAS TOUCHER Calcul'!$BB29,"") | M17: =IF(K17<>"",IF(M16="F","H","F"),"") | O17: Liste 14 | P17: =COUNTIF($H$4:$H$169,$O17) -> 0 | Q17: =COUNTIF($L$4:$L$64,$O17) -> 0
A18: Liste 15 | G18: =IF(G17<>"",IF(($G17+1)<=($E$5+2),G17+1,""),"") -> 14 | H18: =IF(G18<>"",'NE PAS TOUCHER Calcul'!$BB30,"") -> Liste 2 | I18: =IF(G18<>"",IF(I17="F","H","F"),"") -> F | K18: =IF(K17<>"",IF(K17+1<=IF($E$7<5,$E$7+1,$E$7+2),$K17+1,""),"") | L18: =IF(K18<>"",'NE PAS TOUCHER Calcul'!$BB30,"") | M18: =IF(K18<>"",IF(M17="F","H","F"),"") | O18: Liste 15 | P18: =COUNTIF($H$4:$H$169,$O18) -> 0 | Q18: =COUNTIF($L$4:$L$64,$O18) -> 0
A19: Liste 16 | G19: =IF(G18<>"",IF(($G18+1)<=($E$5+2),G18+1,""),"") -> 15 | H19: =IF(G19<>"",'NE PAS TOUCHER Calcul'!$BB31,"") -> Liste 1 | I19: =IF(G19<>"",IF(I18="F","H","F"),"") -> H | K19: =IF(K18<>"",IF(K18+1<=IF($E$7<5,$E$7+1,$E$7+2),$K18+1,""),"") | L19: =IF(K19<>"",'NE PAS TOUCHER Calcul'!$BB31,"") | M19: =IF(K19<>"",IF(M18="F","H","F"),"") | O19: Liste 16 | P19: =COUNTIF($H$4:$H$169,$O19) -> 0 | Q19: =COUNTIF($L$4:$L$64,$O19) -> 0
A20: Liste 17 | G20: =IF(G19<>"",IF(($G19+1)<=($E$5+2),G19+1,""),"") -> 16 | H20: =IF(G20<>"",'NE PAS TOUCHER Calcul'!$BB32,"") -> Liste 2 | I20: =IF(G20<>"",IF(I19="F","H","F"),"") -> F | K20: =IF(K19<>"",IF(K19+1<=IF($E$7<5,$E$7+1,$E$7+2),$K19+1,""),"") | L20: =IF(K20<>"",'NE PAS TOUCHER Calcul'!$BB32,"") | M20: =IF(K20<>"",IF(M19="F","H","F"),"") | O20: Liste 17 | P20: =COUNTIF($H$4:$H$169,$O20) -> 0 | Q20: =COUNTIF($L$4:$L$64,$O20) -> 0
A21: TOTAL | B21: =SUM(B4:B20) -> 41 | G21: =IF(G20<>"",IF(($G20+1)<=($E$5+2),G20+1,""),"") -> 17 | H21: =IF(G21<>"",'NE PAS TOUCHER Calcul'!$BB33,"") -> Liste 1 | I21: =IF(G21<>"",IF(I20="F","H","F"),"") -> H | K21: =IF(K20<>"",IF(K20+1<=IF($E$7<5,$E$7+1,$E$7+2),$K20+1,""),"") | L21: =IF(K21<>"",'NE PAS TOUCHER Calcul'!$BB33,"") | M21: =IF(K21<>"",IF(M20="F","H","F"),"") | O21: TOTAL | P21: =SUM(P4:P20) -> 43 | Q21: =SUM(Q4:Q20) -> 2
G22: =IF(G21<>"",IF(($G21+1)<=($E$5+2),G21+1,""),"") -> 18 | H22: =IF(G22<>"",'NE PAS TOUCHER Calcul'!$BB34,"") -> Liste 2 | I22: =IF(G22<>"",IF(I21="F","H","F"),"") -> F | K22: =IF(K21<>"",IF(K21+1<=IF($E$7<5,$E$7+1,$E$7+2),$K21+1,""),"") | L22: =IF(K22<>"",'NE PAS TOUCHER Calcul'!$BB34,"") | M22: =IF(K22<>"",IF(M21="F","H","F"),"")
G23: =IF(G22<>"",IF(($G22+1)<=($E$5+2),G22+1,""),"") -> 19 | H23: =IF(G23<>"",'NE PAS TOUCHER Calcul'!$BB35,"") -> Liste 1 | I23: =IF(G23<>"",IF(I22="F","H","F"),"") -> H | K23: =IF(K22<>"",IF(K22+1<=IF($E$7<5,$E$7+1,$E$7+2),$K22+1,""),"") | L23: =IF(K23<>"",'NE PAS TOUCHER Calcul'!$BB35,"") | M23: =IF(K23<>"",IF(M22="F","H","F"),"")
G24: =IF(G23<>"",IF(($G23+1)<=($E$5+2),G23+1,""),"") -> 20 | H24: =IF(G24<>"",'NE PAS TOUCHER Calcul'!$BB36,"") -> Liste 2 | I24: =IF(G24<>"",IF(I23="F","H","F"),"") -> F | K24: =IF(K23<>"",IF(K23+1<=IF($E$7<5,$E$7+1,$E$7+2),$K23+1,""),"") | L24: =IF(K24<>"",'NE PAS TOUCHER Calcul'!$BB36,"") | M24: =IF(K24<>"",IF(M23="F","H","F"),"")
G25: =IF(G24<>"",IF(($G24+1)<=($E$5+2),G24+1,""),"") -> 21 | H25: =IF(G25<>"",'NE PAS TOUCHER Calcul'!$BB37,"") -> Liste 1 | I25: =IF(G25<>"",IF(I24="F","H","F"),"") -> H | K25: =IF(K24<>"",IF(K24+1<=IF($E$7<5,$E$7+1,$E$7+2),$K24+1,""),"") | L25: =IF(K25<>"",'NE PAS TOUCHER Calcul'!$BB37,"") | M25: =IF(K25<>"",IF(M24="F","H","F"),"")
G26: =IF(G25<>"",IF(($G25+1)<=($E$5+2),G25+1,""),"") -> 22 | H26: =IF(G26<>"",'NE PAS TOUCHER Calcul'!$BB38,"") -> Liste 2 | I26: =IF(G26<>"",IF(I25="F","H","F"),"") -> F | K26: =IF(K25<>"",IF(K25+1<=IF($E$7<5,$E$7+1,$E$7+2),$K25+1,""),"") | L26: =IF(K26<>"",'NE PAS TOUCHER Calcul'!$BB38,"") | M26: =IF(K26<>"",IF(M25="F","H","F"),"")
G27: =IF(G26<>"",IF(($G26+1)<=($E$5+2),G26+1,""),"") -> 23 | H27: =IF(G27<>"",'NE PAS TOUCHER Calcul'!$BB39,"") -> Liste 1 | I27: =IF(G27<>"",IF(I26="F","H","F"),"") -> H | K27: =IF(K26<>"",IF(K26+1<=IF($E$7<5,$E$7+1,$E$7+2),$K26+1,""),"") | L27: =IF(K27<>"",'NE PAS TOUCHER Calcul'!$BB39,"") | M27: =IF(K27<>"",IF(M26="F","H","F"),"")
G28: =IF(G27<>"",IF(($G27+1)<=($E$5+2),G27+1,""),"") -> 24 | H28: =IF(G28<>"",'NE PAS TOUCHER Calcul'!$BB40,"") -> Liste 2 | I28: =IF(G28<>"",IF(I27="F","H","F"),"") -> F | K28: =IF(K27<>"",IF(K27+1<=IF($E$7<5,$E$7+1,$E$7+2),$K27+1,""),"") | L28: =IF(K28<>"",'NE PAS TOUCHER Calcul'!$BB40,"") | M28: =IF(K28<>"",IF(M27="F","H","F"),"")
G29: =IF(G28<>"",IF(($G28+1)<=($E$5+2),G28+1,""),"") -> 25 | H29: =IF(G29<>"",'NE PAS TOUCHER Calcul'!$BB41,"") -> Liste 1 | I29: =IF(G29<>"",IF(I28="F","H","F"),"") -> H | K29: =IF(K28<>"",IF(K28+1<=IF($E$7<5,$E$7+1,$E$7+2),$K28+1,""),"") | L29: =IF(K29<>"",'NE PAS TOUCHER Calcul'!$BB41,"") | M29: =IF(K29<>"",IF(M28="F","H","F"),"")
G30: =IF(G29<>"",IF(($G29+1)<=($E$5+2),G29+1,""),"") -> 26 | H30: =IF(G30<>"",'NE PAS TOUCHER Calcul'!$BB42,"") -> Liste 2 | I30: =IF(G30<>"",IF(I29="F","H","F"),"") -> F | K30: =IF(K29<>"",IF(K29+1<=IF($E$7<5,$E$7+1,$E$7+2),$K29+1,""),"") | L30: =IF(K30<>"",'NE PAS TOUCHER Calcul'!$BB42,"") | M30: =IF(K30<>"",IF(M29="F","H","F"),"")
G31: =IF(G30<>"",IF(($G30+1)<=($E$5+2),G30+1,""),"") -> 27 | H31: =IF(G31<>"",'NE PAS TOUCHER Calcul'!$BB43,"") -> Liste 2 | I31: =IF(G31<>"",IF(I30="F","H","F"),"") -> H | K31: =IF(K30<>"",IF(K30+1<=IF($E$7<5,$E$7+1,$E$7+2),$K30+1,""),"") | L31: =IF(K31<>"",'NE PAS TOUCHER Calcul'!$BB43,"") | M31: =IF(K31<>"",IF(M30="F","H","F"),"")
G32: =IF(G31<>"",IF(($G31+1)<=($E$5+2),G31+1,""),"") -> 28 | H32: =IF(G32<>"",'NE PAS TOUCHER Calcul'!$BB44,"") -> Liste 1 | I32: =IF(G32<>"",IF(I31="F","H","F"),"") -> F | K32: =IF(K31<>"",IF(K31+1<=IF($E$7<5,$E$7+1,$E$7+2),$K31+1,""),"") | L32: =IF(K32<>"",'NE PAS TOUCHER Calcul'!$BB44,"") | M32: =IF(K32<>"",IF(M31="F","H","F"),"")
G33: =IF(G32<>"",IF(($G32+1)<=($E$5+2),G32+1,""),"") -> 29 | H33: =IF(G33<>"",'NE PAS TOUCHER Calcul'!$BB45,"") -> Liste 2 | I33: =IF(G33<>"",IF(I32="F","H","F"),"") -> H | K33: =IF(K32<>"",IF(K32+1<=IF($E$7<5,$E$7+1,$E$7+2),$K32+1,""),"") | L33: =IF(K33<>"",'NE PAS TOUCHER Calcul'!$BB45,"") | M33: =IF(K33<>"",IF(M32="F","H","F"),"")
... G47: =IF(G46<>"",IF(($G46+1)<=($E$5+2),G46+1,""),"") -> 43 | H47: =IF(G47<>"",'NE PAS TOUCHER Calcul'!$BB59,"") -> Liste 1 | I47: =IF(G47<>"",IF(I46="F","H","F"),"") -> H | K47: =IF(K46<>"",IF(K46+1<=IF($E$7<5,$E$7+1,$E$7+2),$K46+1,""),"") | L47: =IF(K47<>"",'NE PAS TOUCHER Calcul'!$BB59,"") | M47: =IF(K47<>"",IF(M46="F","H","F"),"")
K48: =IF(K47<>"",IF(K47+1<=IF($E$7<5,$E$7+1,$E$7+2),$K47+1,""),"") | L48: =IF(K48<>"",'NE PAS TOUCHER Calcul'!$BB60,"") | M48: =IF(K48<>"",IF(M47="F","H","F"),"")
K49: =IF(K48<>"",IF(K48+1<=IF($E$7<5,$E$7+1,$E$7+2),$K48+1,""),"") | L49: =IF(K49<>"",'NE PAS TOUCHER Calcul'!$BB61,"") | M49: =IF(K49<>"",IF(M48="F","H","F"),"")
G50: =IF(G49<>"",IF(($G49+1)<=($E$5+2),G49+1,""),"") | H50: =IF(G50<>"",'NE PAS TOUCHER Calcul'!$BB62,"") | I50: =IF(G50<>"",IF(I49="F","H","F"),"") | K50: =IF(K49<>"",IF(K49+1<=IF($E$7<5,$E$7+1,$E$7+2),$K49+1,""),"") | L50: =IF(K50<>"",'NE PAS TOUCHER Calcul'!$BB62,"") | M50: =IF(K50<>"",IF(M49="F","H","F"),"")
G51: =IF(G50<>"",IF(($G50+1)<=($E$5+2),G50+1,""),"") | H51: =IF(G51<>"",'NE PAS TOUCHER Calcul'!$BB63,"") | I51: =IF(G51<>"",IF(I50="F","H","F"),"") | K51: =IF(K50<>"",IF(K50+1<=IF($E$7<5,$E$7+1,$E$7+2),$K50+1,""),"") | L51: =IF(K51<>"",'NE PAS TOUCHER Calcul'!$BB63,"") | M51: =IF(K51<>"",IF(M50="F","H","F"),"")
G52: =IF(G51<>"",IF(($G51+1)<=($E$5+2),G51+1,""),"") | H52: =IF(G52<>"",'NE PAS TOUCHER Calcul'!$BB64,"") | I52: =IF(G52<>"",IF(I51="F","H","F"),"") | K52: =IF(K51<>"",IF(K51+1<=IF($E$7<5,$E$7+1,$E$7+2),$K51+1,""),"") | L52: =IF(K52<>"",'NE PAS TOUCHER Calcul'!$BB64,"") | M52: =IF(K52<>"",IF(M51="F","H","F"),"")
G53: =IF(G52<>"",IF(($G52+1)<=($E$5+2),G52+1,""),"") | H53: =IF(G53<>"",'NE PAS TOUCHER Calcul'!$BB65,"") | I53: =IF(G53<>"",IF(I52="F","H","F"),"") | K53: =IF(K52<>"",IF(K52+1<=IF($E$7<5,$E$7+1,$E$7+2),$K52+1,""),"") | L53: =IF(K53<>"",'NE PAS TOUCHER Calcul'!$BB65,"") | M53: =IF(K53<>"",IF(M52="F","H","F"),"")
G54: =IF(G53<>"",IF(($G53+1)<=($E$5+2),G53+1,""),"") | H54: =IF(G54<>"",'NE PAS TOUCHER Calcul'!$BB66,"") | I54: =IF(G54<>"",IF(I53="F","H","F"),"") | K54: =IF(K53<>"",IF(K53+1<=IF($E$7<5,$E$7+1,$E$7+2),$K53+1,""),"") | L54: =IF(K54<>"",'NE PAS TOUCHER Calcul'!$BB66,"") | M54: =IF(K54<>"",IF(M53="F","H","F"),"")
...

Sheet NE PAS TOUCHER  Calcul
A1: Fusion de liste - proportionnelle
B10: {=TRANSPOSE(Résultats!$A$4:$A$20)} -> Liste 1 | C10: Liste 2 | D10: Liste 3 | E10: Liste 4 | F10: Liste 5 | G10: Liste 6 | H10: Liste 7 | I10: Liste 8 | J10: Liste 9 | K10: Liste 10 | L10: Liste 11 | M10: Liste 12 | N10: Liste 13 | O10: Liste 14 | P10: Liste 15 | Q10: Liste 16 | R10: Liste 17
A11: Voix ou % | B11: {=TRANSPOSE(Résultats!$B$4:$B$20)} -> 19 | C11: 22 | D11: 0 | E11: 0 | F11: 0 | G11: 0 | H11: 0 | I11: 0 | J11: 0 | K11: 0 | L11: 0 | M11: 0 | N11: 0 | O11: 0 | P11: 0 | Q11: 0 | R11: 0 | T11: Attribution de chaque siège | AK11: Nombre total de sièges attribués
B12: =IF(B11<>"",B11,0) -> 19 | C12: =IF(C11<>"",C11,0) -> 22 | D12: =IF(D11<>"",D11,0) -> 0 | E12: =IF(E11<>"",E11,0) -> 0 | F12: =IF(F11<>"",F11,0) -> 0 | G12: =IF(G11<>"",G11,0) -> 0 | H12: =IF(H11<>"",H11,0) -> 0 | I12: =IF(I11<>"",I11,0) -> 0 | ... R12: =IF(R11<>"",R11,0) -> 0
T13: attribué à : | U13: attribué à : | V13: attribué à : | W13: attribué à : | X13: attribué à : | Y13: attribué à : | Z13: attribué à : | AA13: attribué à : | AB13: attribué à : | AC13: attribué à : | AD13: attribué à : | AE13: attribué à : | AF13: attribué à : | AG13: attribué à : | AH13: attribué à : | AI13: attribué à : | AJ13: attribué à : | AK13: cumul : | AL13: cumul : | AM13: cumul : | AN13: cumul : | AO13: cumul : | AP13: cumul : | AQ13: cumul : | AR13: cumul : | AS13: cumul : | AT13: cumul : | AU13: cumul : | AV13: cumul : | AW13: cumul : | AX13: cumul : | AY13: cumul : | AZ13: cumul : | BA13: cumul :
B14: =IF(ISBLANK($B$10),"",$B$10) -> Liste 1 | C14: =IF(ISBLANK($C$10),"",$C$10) -> Liste 2 | D14: =IF(ISBLANK($D$10),"",$D$10) -> Liste 3 | E14: =E10 -> Liste 4 | F14: =F10 -> Liste 5 | G14: =G10 -> Liste 6 | H14: =H10 -> Liste 7 | I14: =I10 -> Liste 8 | J14: =J10 -> Liste 9 | K14: =K10 -> Liste 10 | L14: =L10 -> Liste 11 | ... R14: =R10 -> Liste 17 | S14: Calcul maxi | T14: =IF(ISBLANK(B$10),"",B$10) -> Liste 1 | U14: =IF(ISBLANK(C$10),"",C$10) -> Liste 2 | V14: =IF(ISBLANK(D$10),"",D$10) -> Liste 3 | W14: =IF(ISBLANK(E$10),"",E$10) -> Liste 4 | X14: =IF(ISBLANK(F$10),"",F$10) -> Liste 5 | Y14: =IF(ISBLANK(G$10),"",G$10) -> Liste 6 | Z14: =IF(ISBLANK(H$10),"",H$10) -> Liste 7 | AA14: =IF(ISBLANK(I$10),"",I$10) -> Liste 8 | ... AJ14: =IF(ISBLANK(R$10),"",R$10) -> Liste 17 | AK14: =IF(ISBLANK(B$10),"",B$10) -> Liste 1 | AL14: =IF(ISBLANK(C$10),"",C$10) -> Liste 2 | AM14: =IF(ISBLANK(D$10),"",D$10) -> Liste 3 | AN14: =IF(ISBLANK(E$10),"",E$10) -> Liste 4 | AO14: =IF(ISBLANK(F$10),"",F$10) -> Liste 5 | AP14: =IF(ISBLANK(G$10),"",G$10) -> Liste 6 | AQ14: =IF(ISBLANK(H$10),"",H$10) -> Liste 7 | AR14: =IF(ISBLANK(I$10),"",I$10) -> Liste 8 | ... BA14: =IF(ISBLANK(R$10),"",R$10) -> Liste 17
A15: N° Place | B15: Moyenne | C15: Moyenne | D15: Moyenne | E15: Moyenne | F15: Moyenne | G15: Moyenne | H15: Moyenne | I15: Moyenne | J15: Moyenne | K15: Moyenne | L15: Moyenne | M15: Moyenne | N15: Moyenne | O15: Moyenne | P15: Moyenne | Q15: Moyenne | R15: Moyenne
A17: 1 | B17: =B$12/(AK16+1) -> 19 | C17: =C$12/(AL16+1) -> 22 | D17: =D$12/(AM16+1) -> 0 | E17: =E$12/(AN16+1) -> 0 | F17: =F$12/(AO16+1) -> 0 | G17: =G$12/(AP16+1) -> 0 | H17: =H$12/(AQ16+1) -> 0 | I17: =I$12/(AR16+1) -> 0 | ... R17: =R$12/(BA16+1) -> 0 | S17: =MAX(B17:R17) -> 22 | T17: =IF(B17=S17,1,0) -> 0 | U17: =IF(T17=0,IF(C17=S17,1,0),0) -> 1 | V17: =IF(T17+U17=0,IF(D17=S17,1,0),0) -> 0 | W17: =IF(T17+U17+V17=0,IF(E17=S17,1,0),0) -> 0 | X17: =IF(T17+U17+V17+W17=0,IF(F17=S17,1,0),0) -> 0 | Y17: =IF(T17+U17+V17+W17+X17=0,IF(G17=S17,1,0),0) -> 0 | Z17: =IF(T17+U17+V17+W17+X17+Y17=0,IF(H17=S17,1,0),0) -> 0 | AA17: =IF(T17+U17+V17+W17+X17+Y17+Z17=0,IF(I17=S17,1,0),0) -> 0 | AB17: =IF(T17+U17+V17+W17+X17+Y17+Z17+AA17=0,IF(J17=S17,1,0),0) -> 0 | AC17: =IF(T17+U17+V17+W17+X17+Y17+Z17+AA17+AB17=0,IF(K17=S17,1,0),0) -> 0 | AD17: =IF(T17+U17+V17+W17+X17+Y17+Z17+AA17+AB17+AC17=0,IF(L17=S17,1,0),0) -> 0 | AE17: =IF(T17+U17+V17+W17+X17+Y17+Z17+AA17+AB17+AC17+AD17=0,IF(M17=S17,1,0),0) -> 0 | AF17: =IF(T17+U17+V17+W17+X17+Y17+Z17+AA17+AB17+AC17+AD17+AE17=0,IF(N17=S17,1,0),0) -> 0 | AG17: =IF(T17+U17+V17+W17+X17+Y17+Z17+AA17+AB17+AC17+AD17+AE17+AF17=0,IF(O17=S17,1,0),0) -> 0 | AH17: =IF(T17+U17+V17+W17+X17+Y17+Z17+AA17+AB17+AC17+AD17+AE17+AF17+AG17=0,IF(P17=S17,1,0),0) -> 0 | AI17: =IF(T17+U17+V17+W17+X17+Y17+Z17+AA17+AB17+AC17+AD17+AE17+AF17+AG17+AH17=0,IF(Q17=S17,1,0),0) -> 0 | AJ17: =IF(T17+U17+V17+W17+X17+Y17+Z17+AA17+AB17+AC17+AD17+AE17+AF17+AG17+AH17+AI17=0,IF(R17=S17,1,0),0) -> 0 | AK17: =T17+AK16 -> 0 | AL17: =U17+AL16 -> 1 | AM17: =V17+AM16 -> 0 | AN17: =W17+AN16 -> 0 | AO17: =X17+AO16 -> 0 | AP17: =Y17+AP16 -> 0 | AQ17: =Z17+AQ16 -> 0 | AR17: =AA17+AR16 -> 0 | ... BA17: =AJ17+BA16 -> 0 | BB17: =INDEX($T$14:$AJ$15,1,MATCH(1,T17:BA17,0)) -> Liste 2
A18: 2 | B18: =B$12/(AK17+1) -> 19 | C18: =C$12/(AL17+1) -> 11 | D18: =D$12/(AM17+1) -> 0 | E18: =E$12/(AN17+1) -> 0 | F18: =F$12/(AO17+1) -> 0 | G18: =G$12/(AP17+1) -> 0 | H18: =H$12/(AQ17+1) -> 0 | I18: =I$12/(AR17+1) -> 0 | ... R18: =R$12/(BA17+1) -> 0 | S18: =MAX(B18:R18) -> 19 | T18: =IF(B18=S18,1,0) -> 1 | U18: =IF(T18=0,IF(C18=S18,1,0),0) -> 0 | V18: =IF(T18+U18=0,IF(D18=S18,1,0),0) -> 0 | W18: =IF(T18+U18+V18=0,IF(E18=S18,1,0),0) -> 0 | X18: =IF(T18+U18+V18+W18=0,IF(F18=S18,1,0),0) -> 0 | Y18: =IF(T18+U18+V18+W18+X18=0,IF(G18=S18,1,0),0) -> 0 | Z18: =IF(T18+U18+V18+W18+X18+Y18=0,IF(H18=S18,1,0),0) -> 0 | AA18: =IF(T18+U18+V18+W18+X18+Y18+Z18=0,IF(I18=S18,1,0),0) -> 0 | AB18: =IF(T18+U18+V18+W18+X18+Y18+Z18+AA18=0,IF(J18=S18,1,0),0) -> 0 | AC18: =IF(T18+U18+V18+W18+X18+Y18+Z18+AA18+AB18=0,IF(K18=S18,1,0),0) -> 0 | AD18: =IF(T18+U18+V18+W18+X18+Y18+Z18+AA18+AB18+AC18=0,IF(L18=S18,1,0),0) -> 0 | AE18: =IF(T18+U18+V18+W18+X18+Y18+Z18+AA18+AB18+AC18+AD18=0,IF(M18=S18,1,0),0) -> 0 | AF18: =IF(T18+U18+V18+W18+X18+Y18+Z18+AA18+AB18+AC18+AD18+AE18=0,IF(N18=S18,1,0),0) -> 0 | AG18: =IF(T18+U18+V18+W18+X18+Y18+Z18+AA18+AB18+AC18+AD18+AE18+AF18=0,IF(O18=S18,1,0),0) -> 0 | AH18: =IF(T18+U18+V18+W18+X18+Y18+Z18+AA18+AB18+AC18+AD18+AE18+AF18+AG18=0,IF(P18=S18,1,0),0) -> 0 | AI18: =IF(T18+U18+V18+W18+X18+Y18+Z18+AA18+AB18+AC18+AD18+AE18+AF18+AG18+AH18=0,IF(Q18=S18,1,0),0) -> 0 | AJ18: =IF(T18+U18+V18+W18+X18+Y18+Z18+AA18+AB18+AC18+AD18+AE18+AF18+AG18+AH18+AI18=0,IF(R18=S18,1,0),0) -> 0 | AK18: =T18+AK17 -> 1 | AL18: =U18+AL17 -> 1 | AM18: =V18+AM17 -> 0 | AN18: =W18+AN17 -> 0 | AO18: =X18+AO17 -> 0 | AP18: =Y18+AP17 -> 0 | AQ18: =Z18+AQ17 -> 0 | AR18: =AA18+AR17 -> 0 | ... BA18: =AJ18+BA17 -> 0 | BB18: =INDEX($T$14:$AJ$15,1,MATCH(1,T18:BA18,0)) -> Liste 1
A19: 3 | B19: =B$12/(AK18+1) -> 9.5 | C19: =C$12/(AL18+1) -> 11 | D19: =D$12/(AM18+1) -> 0 | E19: =E$12/(AN18+1) -> 0 | F19: =F$12/(AO18+1) -> 0 | G19: =G$12/(AP18+1) -> 0 | H19: =H$12/(AQ18+1) -> 0 | I19: =I$12/(AR18+1) -> 0 | ... R19: =R$12/(BA18+1) -> 0 | S19: =MAX(B19:R19) -> 11 | T19: =IF(B19=S19,1,0) -> 0 | U19: =IF(T19=0,IF(C19=S19,1,0),0) -> 1 | V19: =IF(T19+U19=0,IF(D19=S19,1,0),0) -> 0 | W19: =IF(T19+U19+V19=0,IF(E19=S19,1,0),0) -> 0 | X19: =IF(T19+U19+V19+W19=0,IF(F19=S19,1,0),0) -> 0 | Y19: =IF(T19+U19+V19+W19+X19=0,IF(G19=S19,1,0),0) -> 0 | Z19: =IF(T19+U19+V19+W19+X19+Y19=0,IF(H19=S19,1,0),0) -> 0 | AA19: =IF(T19+U19+V19+W19+X19+Y19+Z19=0,IF(I19=S19,1,0),0) -> 0 | AB19: =IF(T19+U19+V19+W19+X19+Y19+Z19+AA19=0,IF(J19=S19,1,0),0) -> 0 | AC19: =IF(T19+U19+V19+W19+X19+Y19+Z19+AA19+AB19=0,IF(K19=S19,1,0),0) -> 0 | AD19: =IF(T19+U19+V19+W19+X19+Y19+Z19+AA19+AB19+AC19=0,IF(L19=S19,1,0),0) -> 0 | AE19: =IF(T19+U19+V19+W19+X19+Y19+Z19+AA19+AB19+AC19+AD19=0,IF(M19=S19,1,0),0) -> 0 | AF19: =IF(T19+U19+V19+W19+X19+Y19+Z19+AA19+AB19+AC19+AD19+AE19=0,IF(N19=S19,1,0),0) -> 0 | AG19: =IF(T19+U19+V19+W19+X19+Y19+Z19+AA19+AB19+AC19+AD19+AE19+AF19=0,IF(O19=S19,1,0),0) -> 0 | AH19: =IF(T19+U19+V19+W19+X19+Y19+Z19+AA19+AB19+AC19+AD19+AE19+AF19+AG19=0,IF(P19=S19,1,0),0) -> 0 | AI19: =IF(T19+U19+V19+W19+X19+Y19+Z19+AA19+AB19+AC19+AD19+AE19+AF19+AG19+AH19=0,IF(Q19=S19,1,0),0) -> 0 | AJ19: =IF(T19+U19+V19+W19+X19+Y19+Z19+AA19+AB19+AC19+AD19+AE19+AF19+AG19+AH19+AI19=0,IF(R19=S19,1,0),0) -> 0 | AK19: =T19+AK18 -> 1 | AL19: =U19+AL18 -> 2 | AM19: =V19+AM18 -> 0 | AN19: =W19+AN18 -> 0 | AO19: =X19+AO18 -> 0 | AP19: =Y19+AP18 -> 0 | AQ19: =Z19+AQ18 -> 0 | AR19: =AA19+AR18 -> 0 | ... BA19: =AJ19+BA18 -> 0 | BB19: =INDEX($T$14:$AJ$15,1,MATCH(1,T19:BA19,0)) -> Liste 2
A20: 4 | B20: =B$12/(AK19+1) -> 9.5 | C20: =C$12/(AL19+1) -> 7.3333333 | D20: =D$12/(AM19+1) -> 0 | E20: =E$12/(AN19+1) -> 0 | F20: =F$12/(AO19+1) -> 0 | G20: =G$12/(AP19+1) -> 0 | H20: =H$12/(AQ19+1) -> 0 | I20: =I$12/(AR19+1) -> 0 | ... R20: =R$12/(BA19+1) -> 0 | S20: =MAX(B20:R20) -> 9.5 | T20: =IF(B20=S20,1,0) -> 1 | U20: =IF(T20=0,IF(C20=S20,1,0),0) -> 0 | V20: =IF(T20+U20=0,IF(D20=S20,1,0),0) -> 0 | W20: =IF(T20+U20+V20=0,IF(E20=S20,1,0),0) -> 0 | X20: =IF(T20+U20+V20+W20=0,IF(F20=S20,1,0),0) -> 0 | Y20: =IF(T20+U20+V20+W20+X20=0,IF(G20=S20,1,0),0) -> 0 | Z20: =IF(T20+U20+V20+W20+X20+Y20=0,IF(H20=S20,1,0),0) -> 0 | AA20: =IF(T20+U20+V20+W20+X20+Y20+Z20=0,IF(I20=S20,1,0),0) -> 0 | AB20: =IF(T20+U20+V20+W20+X20+Y20+Z20+AA20=0,IF(J20=S20,1,0),0) -> 0 | AC20: =IF(T20+U20+V20+W20+X20+Y20+Z20+AA20+AB20=0,IF(K20=S20,1,0),0) -> 0 | AD20: =IF(T20+U20+V20+W20+X20+Y20+Z20+AA20+AB20+AC20=0,IF(L20=S20,1,0),0) -> 0 | AE20: =IF(T20+U20+V20+W20+X20+Y20+Z20+AA20+AB20+AC20+AD20=0,IF(M20=S20,1,0),0) -> 0 | AF20: =IF(T20+U20+V20+W20+X20+Y20+Z20+AA20+AB20+AC20+AD20+AE20=0,IF(N20=S20,1,0),0) -> 0 | AG20: =IF(T20+U20+V20+W20+X20+Y20+Z20+AA20+AB20+AC20+AD20+AE20+AF20=0,IF(O20=S20,1,0),0) -> 0 | AH20: =IF(T20+U20+V20+W20+X20+Y20+Z20+AA20+AB20+AC20+AD20+AE20+AF20+AG20=0,IF(P20=S20,1,0),0) -> 0 | AI20: =IF(T20+U20+V20+W20+X20+Y20+Z20+AA20+AB20+AC20+AD20+AE20+AF20+AG20+AH20=0,IF(Q20=S20,1,0),0) -> 0 | AJ20: =IF(T20+U20+V20+W20+X20+Y20+Z20+AA20+AB20+AC20+AD20+AE20+AF20+AG20+AH20+AI20=0,IF(R20=S20,1,0),0) -> 0 | AK20: =T20+AK19 -> 2 | AL20: =U20+AL19 -> 2 | AM20: =V20+AM19 -> 0 | AN20: =W20+AN19 -> 0 | AO20: =X20+AO19 -> 0 | AP20: =Y20+AP19 -> 0 | AQ20: =Z20+AQ19 -> 0 | AR20: =AA20+AR19 -> 0 | ... BA20: =AJ20+BA19 -> 0 | BB20: =INDEX($T$14:$AJ$15,1,MATCH(1,T20:BA20,0)) -> Liste 1
A21: 5 | B21: =B$12/(AK20+1) -> 6.3333333 | C21: =C$12/(AL20+1) -> 7.3333333 | D21: =D$12/(AM20+1) -> 0 | E21: =E$12/(AN20+1) -> 0 | F21: =F$12/(AO20+1) -> 0 | G21: =G$12/(AP20+1) -> 0 | H21: =H$12/(AQ20+1) -> 0 | I21: =I$12/(AR20+1) -> 0 | ... R21: =R$12/(BA20+1) -> 0 | S21: =MAX(B21:R21) -> 7.3333333 | T21: =IF(B21=S21,1,0) -> 0 | U21: =IF(T21=0,IF(C21=S21,1,0),0) -> 1 | V21: =IF(T21+U21=0,IF(D21=S21,1,0),0) -> 0 | W21: =IF(T21+U21+V21=0,IF(E21=S21,1,0),0) -> 0 | X21: =IF(T21+U21+V21+W21=0,IF(F21=S21,1,0),0) -> 0 | Y21: =IF(T21+U21+V21+W21+X21=0,IF(G21=S21,1,0),0) -> 0 | Z21: =IF(T21+U21+V21+W21+X21+Y21=0,IF(H21=S21,1,0),0) -> 0 | AA21: =IF(T21+U21+V21+W21+X21+Y21+Z21=0,IF(I21=S21,1,0),0) -> 0 | AB21: =IF(T21+U21+V21+W21+X21+Y21+Z21+AA21=0,IF(J21=S21,1,0),0) -> 0 | AC21: =IF(T21+U21+V21+W21+X21+Y21+Z21+AA21+AB21=0,IF(K21=S21,1,0),0) -> 0 | AD21: =IF(T21+U21+V21+W21+X21+Y21+Z21+AA21+AB21+AC21=0,IF(L21=S21,1,0),0) -> 0 | AE21: =IF(T21+U21+V21+W21+X21+Y21+Z21+AA21+AB21+AC21+AD21=0,IF(M21=S21,1,0),0) -> 0 | AF21: =IF(T21+U21+V21+W21+X21+Y21+Z21+AA21+AB21+AC21+AD21+AE21=0,IF(N21=S21,1,0),0) -> 0 | AG21: =IF(T21+U21+V21+W21+X21+Y21+Z21+AA21+AB21+AC21+AD21+AE21+AF21=0,IF(O21=S21,1,0),0) -> 0 | AH21: =IF(T21+U21+V21+W21+X21+Y21+Z21+AA21+AB21+AC21+AD21+AE21+AF21+AG21=0,IF(P21=S21,1,0),0) -> 0 | AI21: =IF(T21+U21+V21+W21+X21+Y21+Z21+AA21+AB21+AC21+AD21+AE21+AF21+AG21+AH21=0,IF(Q21=S21,1,0),0) -> 0 | AJ21: =IF(T21+U21+V21+W21+X21+Y21+Z21+AA21+AB21+AC21+AD21+AE21+AF21+AG21+AH21+AI21=0,IF(R21=S21,1,0),0) -> 0 | AK21: =T21+AK20 -> 2 | AL21: =U21+AL20 -> 3 | AM21: =V21+AM20 -> 0 | AN21: =W21+AN20 -> 0 | AO21: =X21+AO20 -> 0 | AP21: =Y21+AP20 -> 0 | AQ21: =Z21+AQ20 -> 0 | AR21: =AA21+AR20 -> 0 | ... BA21: =AJ21+BA20 -> 0 | BB21: =INDEX($T$14:$AJ$15,1,MATCH(1,T21:BA21,0)) -> Liste 2
A22: 6 | B22: =B$12/(AK21+1) -> 6.3333333 | C22: =C$12/(AL21+1) -> 5.5 | D22: =D$12/(AM21+1) -> 0 | E22: =E$12/(AN21+1) -> 0 | F22: =F$12/(AO21+1) -> 0 | G22: =G$12/(AP21+1) -> 0 | H22: =H$12/(AQ21+1) -> 0 | I22: =I$12/(AR21+1) -> 0 | ... R22: =R$12/(BA21+1) -> 0 | S22: =MAX(B22:R22) -> 6.3333333 | T22: =IF(B22=S22,1,0) -> 1 | U22: =IF(T22=0,IF(C22=S22,1,0),0) -> 0 | V22: =IF(T22+U22=0,IF(D22=S22,1,0),0) -> 0 | W22: =IF(T22+U22+V22=0,IF(E22=S22,1,0),0) -> 0 | X22: =IF(T22+U22+V22+W22=0,IF(F22=S22,1,0),0) -> 0 | Y22: =IF(T22+U22+V22+W22+X22=0,IF(G22=S22,1,0),0) -> 0 | Z22: =IF(T22+U22+V22+W22+X22+Y22=0,IF(H22=S22,1,0),0) -> 0 | AA22: =IF(T22+U22+V22+W22+X22+Y22+Z22=0,IF(I22=S22,1,0),0) -> 0 | AB22: =IF(T22+U22+V22+W22+X22+Y22+Z22+AA22=0,IF(J22=S22,1,0),0) -> 0 | AC22: =IF(T22+U22+V22+W22+X22+Y22+Z22+AA22+AB22=0,IF(K22=S22,1,0),0) -> 0 | AD22: =IF(T22+U22+V22+W22+X22+Y22+Z22+AA22+AB22+AC22=0,IF(L22=S22,1,0),0) -> 0 | AE22: =IF(T22+U22+V22+W22+X22+Y22+Z22+AA22+AB22+AC22+AD22=0,IF(M22=S22,1,0),0) -> 0 | AF22: =IF(T22+U22+V22+W22+X22+Y22+Z22+AA22+AB22+AC22+AD22+AE22=0,IF(N22=S22,1,0),0) -> 0 | AG22: =IF(T22+U22+V22+W22+X22+Y22+Z22+AA22+AB22+AC22+AD22+AE22+AF22=0,IF(O22=S22,1,0),0) -> 0 | AH22: =IF(T22+U22+V22+W22+X22+Y22+Z22+AA22+AB22+AC22+AD22+AE22+AF22+AG22=0,IF(P22=S22,1,0),0) -> 0 | AI22: =IF(T22+U22+V22+W22+X22+Y22+Z22+AA22+AB22+AC22+AD22+AE22+AF22+AG22+AH22=0,IF(Q22=S22,1,0),0) -> 0 | AJ22: =IF(T22+U22+V22+W22+X22+Y22+Z22+AA22+AB22+AC22+AD22+AE22+AF22+AG22+AH22+AI22=0,IF(R22=S22,1,0),0) -> 0 | AK22: =T22+AK21 -> 3 | AL22: =U22+AL21 -> 3 | AM22: =V22+AM21 -> 0 | AN22: =W22+AN21 -> 0 | AO22: =X22+AO21 -> 0 | AP22: =Y22+AP21 -> 0 | AQ22: =Z22+AQ21 -> 0 | AR22: =AA22+AR21 -> 0 | ... BA22: =AJ22+BA21 -> 0 | BB22: =INDEX($T$14:$AJ$15,1,MATCH(1,T22:BA22,0)) -> Liste 1
A23: 7 | B23: =B$12/(AK22+1) -> 4.75 | C23: =C$12/(AL22+1) -> 5.5 | D23: =D$12/(AM22+1) -> 0 | E23: =E$12/(AN22+1) -> 0 | F23: =F$12/(AO22+1) -> 0 | G23: =G$12/(AP22+1) -> 0 | H23: =H$12/(AQ22+1) -> 0 | I23: =I$12/(AR22+1) -> 0 | ... R23: =R$12/(BA22+1) -> 0 | S23: =MAX(B23:R23) -> 5.5 | T23: =IF(B23=S23,1,0) -> 0 | U23: =IF(T23=0,IF(C23=S23,1,0),0) -> 1 | V23: =IF(T23+U23=0,IF(D23=S23,1,0),0) -> 0 | W23: =IF(T23+U23+V23=0,IF(E23=S23,1,0),0) -> 0 | X23: =IF(T23+U23+V23+W23=0,IF(F23=S23,1,0),0) -> 0 | Y23: =IF(T23+U23+V23+W23+X23=0,IF(G23=S23,1,0),0) -> 0 | Z23: =IF(T23+U23+V23+W23+X23+Y23=0,IF(H23=S23,1,0),0) -> 0 | AA23: =IF(T23+U23+V23+W23+X23+Y23+Z23=0,IF(I23=S23,1,0),0) -> 0 | AB23: =IF(T23+U23+V23+W23+X23+Y23+Z23+AA23=0,IF(J23=S23,1,0),0) -> 0 | AC23: =IF(T23+U23+V23+W23+X23+Y23+Z23+AA23+AB23=0,IF(K23=S23,1,0),0) -> 0 | AD23: =IF(T23+U23+V23+W23+X23+Y23+Z23+AA23+AB23+AC23=0,IF(L23=S23,1,0),0) -> 0 | AE23: =IF(T23+U23+V23+W23+X23+Y23+Z23+AA23+AB23+AC23+AD23=0,IF(M23=S23,1,0),0) -> 0 | AF23: =IF(T23+U23+V23+W23+X23+Y23+Z23+AA23+AB23+AC23+AD23+AE23=0,IF(N23=S23,1,0),0) -> 0 | AG23: =IF(T23+U23+V23+W23+X23+Y23+Z23+AA23+AB23+AC23+AD23+AE23+AF23=0,IF(O23=S23,1,0),0) -> 0 | AH23: =IF(T23+U23+V23+W23+X23+Y23+Z23+AA23+AB23+AC23+AD23+AE23+AF23+AG23=0,IF(P23=S23,1,0),0) -> 0 | AI23: =IF(T23+U23+V23+W23+X23+Y23+Z23+AA23+AB23+AC23+AD23+AE23+AF23+AG23+AH23=0,IF(Q23=S23,1,0),0) -> 0 | AJ23: =IF(T23+U23+V23+W23+X23+Y23+Z23+AA23+AB23+AC23+AD23+AE23+AF23+AG23+AH23+AI23=0,IF(R23=S23,1,0),0) -> 0 | AK23: =T23+AK22 -> 3 | AL23: =U23+AL22 -> 4 | AM23: =V23+AM22 -> 0 | AN23: =W23+AN22 -> 0 | AO23: =X23+AO22 -> 0 | AP23: =Y23+AP22 -> 0 | AQ23: =Z23+AQ22 -> 0 | AR23: =AA23+AR22 -> 0 | ... BA23: =AJ23+BA22 -> 0 | BB23: =INDEX($T$14:$AJ$15,1,MATCH(1,T23:BA23,0)) -> Liste 2
A24: 8 | B24: =B$12/(AK23+1) -> 4.75 | C24: =C$12/(AL23+1) -> 4.4 | D24: =D$12/(AM23+1) -> 0 | E24: =E$12/(AN23+1) -> 0 | F24: =F$12/(AO23+1) -> 0 | G24: =G$12/(AP23+1) -> 0 | H24: =H$12/(AQ23+1) -> 0 | I24: =I$12/(AR23+1) -> 0 | ... R24: =R$12/(BA23+1) -> 0 | S24: =MAX(B24:R24) -> 4.75 | T24: =IF(B24=S24,1,0) -> 1 | U24: =IF(T24=0,IF(C24=S24,1,0),0) -> 0 | V24: =IF(T24+U24=0,IF(D24=S24,1,0),0) -> 0 | W24: =IF(T24+U24+V24=0,IF(E24=S24,1,0),0) -> 0 | X24: =IF(T24+U24+V24+W24=0,IF(F24=S24,1,0),0) -> 0 | Y24: =IF(T24+U24+V24+W24+X24=0,IF(G24=S24,1,0),0) -> 0 | Z24: =IF(T24+U24+V24+W24+X24+Y24=0,IF(H24=S24,1,0),0) -> 0 | AA24: =IF(T24+U24+V24+W24+X24+Y24+Z24=0,IF(I24=S24,1,0),0) -> 0 | AB24: =IF(T24+U24+V24+W24+X24+Y24+Z24+AA24=0,IF(J24=S24,1,0),0) -> 0 | AC24: =IF(T24+U24+V24+W24+X24+Y24+Z24+AA24+AB24=0,IF(K24=S24,1,0),0) -> 0 | AD24: =IF(T24+U24+V24+W24+X24+Y24+Z24+AA24+AB24+AC24=0,IF(L24=S24,1,0),0) -> 0 | AE24: =IF(T24+U24+V24+W24+X24+Y24+Z24+AA24+AB24+AC24+AD24=0,IF(M24=S24,1,0),0) -> 0 | AF24: =IF(T24+U24+V24+W24+X24+Y24+Z24+AA24+AB24+AC24+AD24+AE24=0,IF(N24=S24,1,0),0) -> 0 | AG24: =IF(T24+U24+V24+W24+X24+Y24+Z24+AA24+AB24+AC24+AD24+AE24+AF24=0,IF(O24=S24,1,0),0) -> 0 | AH24: =IF(T24+U24+V24+W24+X24+Y24+Z24+AA24+AB24+AC24+AD24+AE24+AF24+AG24=0,IF(P24=S24,1,0),0) -> 0 | AI24: =IF(T24+U24+V24+W24+X24+Y24+Z24+AA24+AB24+AC24+AD24+AE24+AF24+AG24+AH24=0,IF(Q24=S24,1,0),0) -> 0 | AJ24: =IF(T24+U24+V24+W24+X24+Y24+Z24+AA24+AB24+AC24+AD24+AE24+AF24+AG24+AH24+AI24=0,IF(R24=S24,1,0),0) -> 0 | AK24: =T24+AK23 -> 4 | AL24: =U24+AL23 -> 4 | AM24: =V24+AM23 -> 0 | AN24: =W24+AN23 -> 0 | AO24: =X24+AO23 -> 0 | AP24: =Y24+AP23 -> 0 | AQ24: =Z24+AQ23 -> 0 | AR24: =AA24+AR23 -> 0 | ... BA24: =AJ24+BA23 -> 0 | BB24: =INDEX($T$14:$AJ$15,1,MATCH(1,T24:BA24,0)) -> Liste 1
A25: 9 | B25: =B$12/(AK24+1) -> 3.8 | C25: =C$12/(AL24+1) -> 4.4 | D25: =D$12/(AM24+1) -> 0 | E25: =E$12/(AN24+1) -> 0 | F25: =F$12/(AO24+1) -> 0 | G25: =G$12/(AP24+1) -> 0 | H25: =H$12/(AQ24+1) -> 0 | I25: =I$12/(AR24+1) -> 0 | ... R25: =R$12/(BA24+1) -> 0 | S25: =MAX(B25:R25) -> 4.4 | T25: =IF(B25=S25,1,0) -> 0 | U25: =IF(T25=0,IF(C25=S25,1,0),0) -> 1 | V25: =IF(T25+U25=0,IF(D25=S25,1,0),0) -> 0 | W25: =IF(T25+U25+V25=0,IF(E25=S25,1,0),0) -> 0 | X25: =IF(T25+U25+V25+W25=0,IF(F25=S25,1,0),0) -> 0 | Y25: =IF(T25+U25+V25+W25+X25=0,IF(G25=S25,1,0),0) -> 0 | Z25: =IF(T25+U25+V25+W25+X25+Y25=0,IF(H25=S25,1,0),0) -> 0 | AA25: =IF(T25+U25+V25+W25+X25+Y25+Z25=0,IF(I25=S25,1,0),0) -> 0 | AB25: =IF(T25+U25+V25+W25+X25+Y25+Z25+AA25=0,IF(J25=S25,1,0),0) -> 0 | AC25: =IF(T25+U25+V25+W25+X25+Y25+Z25+AA25+AB25=0,IF(K25=S25,1,0),0) -> 0 | AD25: =IF(T25+U25+V25+W25+X25+Y25+Z25+AA25+AB25+AC25=0,IF(L25=S25,1,0),0) -> 0 | AE25: =IF(T25+U25+V25+W25+X25+Y25+Z25+AA25+AB25+AC25+AD25=0,IF(M25=S25,1,0),0) -> 0 | AF25: =IF(T25+U25+V25+W25+X25+Y25+Z25+AA25+AB25+AC25+AD25+AE25=0,IF(N25=S25,1,0),0) -> 0 | AG25: =IF(T25+U25+V25+W25+X25+Y25+Z25+AA25+AB25+AC25+AD25+AE25+AF25=0,IF(O25=S25,1,0),0) -> 0 | AH25: =IF(T25+U25+V25+W25+X25+Y25+Z25+AA25+AB25+AC25+AD25+AE25+AF25+AG25=0,IF(P25=S25,1,0),0) -> 0 | AI25: =IF(T25+U25+V25+W25+X25+Y25+Z25+AA25+AB25+AC25+AD25+AE25+AF25+AG25+AH25=0,IF(Q25=S25,1,0),0) -> 0 | AJ25: =IF(T25+U25+V25+W25+X25+Y25+Z25+AA25+AB25+AC25+AD25+AE25+AF25+AG25+AH25+AI25=0,IF(R25=S25,1,0),0) -> 0 | AK25: =T25+AK24 -> 4 | AL25: =U25+AL24 -> 5 | AM25: =V25+AM24 -> 0 | AN25: =W25+AN24 -> 0 | AO25: =X25+AO24 -> 0 | AP25: =Y25+AP24 -> 0 | AQ25: =Z25+AQ24 -> 0 | AR25: =AA25+AR24 -> 0 | ... BA25: =AJ25+BA24 -> 0 | BB25: =INDEX($T$14:$AJ$15,1,MATCH(1,T25:BA25,0)) -> Liste 2
A26: 10 | B26: =B$12/(AK25+1) -> 3.8 | C26: =C$12/(AL25+1) -> 3.6666667 | D26: =D$12/(AM25+1) -> 0 | E26: =E$12/(AN25+1) -> 0 | F26: =F$12/(AO25+1) -> 0 | G26: =G$12/(AP25+1) -> 0 | H26: =H$12/(AQ25+1) -> 0 | I26: =I$12/(AR25+1) -> 0 | ... R26: =R$12/(BA25+1) -> 0 | S26: =MAX(B26:R26) -> 3.8 | T26: =IF(B26=S26,1,0) -> 1 | U26: =IF(T26=0,IF(C26=S26,1,0),0) -> 0 | V26: =IF(T26+U26=0,IF(D26=S26,1,0),0) -> 0 | W26: =IF(T26+U26+V26=0,IF(E26=S26,1,0),0) -> 0 | X26: =IF(T26+U26+V26+W26=0,IF(F26=S26,1,0),0) -> 0 | Y26: =IF(T26+U26+V26+W26+X26=0,IF(G26=S26,1,0),0) -> 0 | Z26: =IF(T26+U26+V26+W26+X26+Y26=0,IF(H26=S26,1,0),0) -> 0 | AA26: =IF(T26+U26+V26+W26+X26+Y26+Z26=0,IF(I26=S26,1,0),0) -> 0 | AB26: =IF(T26+U26+V26+W26+X26+Y26+Z26+AA26=0,IF(J26=S26,1,0),0) -> 0 | AC26: =IF(T26+U26+V26+W26+X26+Y26+Z26+AA26+AB26=0,IF(K26=S26,1,0),0) -> 0 | AD26: =IF(T26+U26+V26+W26+X26+Y26+Z26+AA26+AB26+AC26=0,IF(L26=S26,1,0),0) -> 0 | AE26: =IF(T26+U26+V26+W26+X26+Y26+Z26+AA26+AB26+AC26+AD26=0,IF(M26=S26,1,0),0) -> 0 | AF26: =IF(T26+U26+V26+W26+X26+Y26+Z26+AA26+AB26+AC26+AD26+AE26=0,IF(N26=S26,1,0),0) -> 0 | AG26: =IF(T26+U26+V26+W26+X26+Y26+Z26+AA26+AB26+AC26+AD26+AE26+AF26=0,IF(O26=S26,1,0),0) -> 0 | AH26: =IF(T26+U26+V26+W26+X26+Y26+Z26+AA26+AB26+AC26+AD26+AE26+AF26+AG26=0,IF(P26=S26,1,0),0) -> 0 | AI26: =IF(T26+U26+V26+W26+X26+Y26+Z26+AA26+AB26+AC26+AD26+AE26+AF26+AG26+AH26=0,IF(Q26=S26,1,0),0) -> 0 | AJ26: =IF(T26+U26+V26+W26+X26+Y26+Z26+AA26+AB26+AC26+AD26+AE26+AF26+AG26+AH26+AI26=0,IF(R26=S26,1,0),0) -> 0 | AK26: =T26+AK25 -> 5 | AL26: =U26+AL25 -> 5 | AM26: =V26+AM25 -> 0 | AN26: =W26+AN25 -> 0 | AO26: =X26+AO25 -> 0 | AP26: =Y26+AP25 -> 0 | AQ26: =Z26+AQ25 -> 0 | AR26: =AA26+AR25 -> 0 | ... BA26: =AJ26+BA25 -> 0 | BB26: =INDEX($T$14:$AJ$15,1,MATCH(1,T26:BA26,0)) -> Liste 1
A27: 11 | B27: =B$12/(AK26+1) -> 3.1666667 | C27: =C$12/(AL26+1) -> 3.6666667 | D27: =D$12/(AM26+1) -> 0 | E27: =E$12/(AN26+1) -> 0 | F27: =F$12/(AO26+1) -> 0 | G27: =G$12/(AP26+1) -> 0 | H27: =H$12/(AQ26+1) -> 0 | I27: =I$12/(AR26+1) -> 0 | ... R27: =R$12/(BA26+1) -> 0 | S27: =MAX(B27:R27) -> 3.6666667 | T27: =IF(B27=S27,1,0) -> 0 | U27: =IF(T27=0,IF(C27=S27,1,0),0) -> 1 | V27: =IF(T27+U27=0,IF(D27=S27,1,0),0) -> 0 | W27: =IF(T27+U27+V27=0,IF(E27=S27,1,0),0) -> 0 | X27: =IF(T27+U27+V27+W27=0,IF(F27=S27,1,0),0) -> 0 | Y27: =IF(T27+U27+V27+W27+X27=0,IF(G27=S27,1,0),0) -> 0 | Z27: =IF(T27+U27+V27+W27+X27+Y27=0,IF(H27=S27,1,0),0) -> 0 | AA27: =IF(T27+U27+V27+W27+X27+Y27+Z27=0,IF(I27=S27,1,0),0) -> 0 | AB27: =IF(T27+U27+V27+W27+X27+Y27+Z27+AA27=0,IF(J27=S27,1,0),0) -> 0 | AC27: =IF(T27+U27+V27+W27+X27+Y27+Z27+AA27+AB27=0,IF(K27=S27,1,0),0) -> 0 | AD27: =IF(T27+U27+V27+W27+X27+Y27+Z27+AA27+AB27+AC27=0,IF(L27=S27,1,0),0) -> 0 | AE27: =IF(T27+U27+V27+W27+X27+Y27+Z27+AA27+AB27+AC27+AD27=0,IF(M27=S27,1,0),0) -> 0 | AF27: =IF(T27+U27+V27+W27+X27+Y27+Z27+AA27+AB27+AC27+AD27+AE27=0,IF(N27=S27,1,0),0) -> 0 | AG27: =IF(T27+U27+V27+W27+X27+Y27+Z27+AA27+AB27+AC27+AD27+AE27+AF27=0,IF(O27=S27,1,0),0) -> 0 | AH27: =IF(T27+U27+V27+W27+X27+Y27+Z27+AA27+AB27+AC27+AD27+AE27+AF27+AG27=0,IF(P27=S27,1,0),0) -> 0 | AI27: =IF(T27+U27+V27+W27+X27+Y27+Z27+AA27+AB27+AC27+AD27+AE27+AF27+AG27+AH27=0,IF(Q27=S27,1,0),0) -> 0 | AJ27: =IF(T27+U27+V27+W27+X27+Y27+Z27+AA27+AB27+AC27+AD27+AE27+AF27+AG27+AH27+AI27=0,IF(R27=S27,1,0),0) -> 0 | AK27: =T27+AK26 -> 5 | AL27: =U27+AL26 -> 6 | AM27: =V27+AM26 -> 0 | AN27: =W27+AN26 -> 0 | AO27: =X27+AO26 -> 0 | AP27: =Y27+AP26 -> 0 | AQ27: =Z27+AQ26 -> 0 | AR27: =AA27+AR26 -> 0 | ... BA27: =AJ27+BA26 -> 0 | BB27: =INDEX($T$14:$AJ$15,1,MATCH(1,T27:BA27,0)) -> Liste 2
A28: 12 | B28: =B$12/(AK27+1) -> 3.1666667 | C28: =C$12/(AL27+1) -> 3.1428571 | D28: =D$12/(AM27+1) -> 0 | E28: =E$12/(AN27+1) -> 0 | F28: =F$12/(AO27+1) -> 0 | G28: =G$12/(AP27+1) -> 0 | H28: =H$12/(AQ27+1) -> 0 | I28: =I$12/(AR27+1) -> 0 | ... R28: =R$12/(BA27+1) -> 0 | S28: =MAX(B28:R28) -> 3.1666667 | T28: =IF(B28=S28,1,0) -> 1 | U28: =IF(T28=0,IF(C28=S28,1,0),0) -> 0 | V28: =IF(T28+U28=0,IF(D28=S28,1,0),0) -> 0 | W28: =IF(T28+U28+V28=0,IF(E28=S28,1,0),0) -> 0 | X28: =IF(T28+U28+V28+W28=0,IF(F28=S28,1,0),0) -> 0 | Y28: =IF(T28+U28+V28+W28+X28=0,IF(G28=S28,1,0),0) -> 0 | Z28: =IF(T28+U28+V28+W28+X28+Y28=0,IF(H28=S28,1,0),0) -> 0 | AA28: =IF(T28+U28+V28+W28+X28+Y28+Z28=0,IF(I28=S28,1,0),0) -> 0 | AB28: =IF(T28+U28+V28+W28+X28+Y28+Z28+AA28=0,IF(J28=S28,1,0),0) -> 0 | AC28: =IF(T28+U28+V28+W28+X28+Y28+Z28+AA28+AB28=0,IF(K28=S28,1,0),0) -> 0 | AD28: =IF(T28+U28+V28+W28+X28+Y28+Z28+AA28+AB28+AC28=0,IF(L28=S28,1,0),0) -> 0 | AE28: =IF(T28+U28+V28+W28+X28+Y28+Z28+AA28+AB28+AC28+AD28=0,IF(M28=S28,1,0),0) -> 0 | AF28: =IF(T28+U28+V28+W28+X28+Y28+Z28+AA28+AB28+AC28+AD28+AE28=0,IF(N28=S28,1,0),0) -> 0 | AG28: =IF(T28+U28+V28+W28+X28+Y28+Z28+AA28+AB28+AC28+AD28+AE28+AF28=0,IF(O28=S28,1,0),0) -> 0 | AH28: =IF(T28+U28+V28+W28+X28+Y28+Z28+AA28+AB28+AC28+AD28+AE28+AF28+AG28=0,IF(P28=S28,1,0),0) -> 0 | AI28: =IF(T28+U28+V28+W28+X28+Y28+Z28+AA28+AB28+AC28+AD28+AE28+AF28+AG28+AH28=0,IF(Q28=S28,1,0),0) -> 0 | AJ28: =IF(T28+U28+V28+W28+X28+Y28+Z28+AA28+AB28+AC28+AD28+AE28+AF28+AG28+AH28+AI28=0,IF(R28=S28,1,0),0) -> 0 | AK28: =T28+AK27 -> 6 | AL28: =U28+AL27 -> 6 | AM28: =V28+AM27 -> 0 | AN28: =W28+AN27 -> 0 | AO28: =X28+AO27 -> 0 | AP28: =Y28+AP27 -> 0 | AQ28: =Z28+AQ27 -> 0 | AR28: =AA28+AR27 -> 0 | ... BA28: =AJ28+BA27 -> 0 | BB28: =INDEX($T$14:$AJ$15,1,MATCH(1,T28:BA28,0)) -> Liste 1
... A181: 165 | B181: =B$12/(AK180+1) -> 0.24675325 | C181: =C$12/(AL180+1) -> 0.24719101 | D181: =D$12/(AM180+1) -> 0 | E181: =E$12/(AN180+1) -> 0 | F181: =F$12/(AO180+1) -> 0 | G181: =G$12/(AP180+1) -> 0 | H181: =H$12/(AQ180+1) -> 0 | I181: =I$12/(AR180+1) -> 0 | ... R181: =R$12/(BA180+1) -> 0 | S181: =MAX(B181:R181) -> 0.24719101 | T181: =IF(B181=S181,1,0) -> 0 | U181: =IF(T181=0,IF(C181=S181,1,0),0) -> 1 | V181: =IF(T181+U181=0,IF(D181=S181,1,0),0) -> 0 | W181: =IF(T181+U181+V181=0,IF(E181=S181,1,0),0) -> 0 | X181: =IF(T181+U181+V181+W181=0,IF(F181=S181,1,0),0) -> 0 | Y181: =IF(T181+U181+V181+W181+X181=0,IF(G181=S181,1,0),0) -> 0 | Z181: =IF(T181+U181+V181+W181+X181+Y181=0,IF(H181=S181,1,0),0) -> 0 | AA181: =IF(T181+U181+V181+W181+X181+Y181+Z181=0,IF(I181=S181,1,0),0) -> 0 | AB181: =IF(T181+U181+V181+W181+X181+Y181+Z181+AA181=0,IF(J181=S181,1,0),0) -> 0 | AC181: =IF(T181+U181+V181+W181+X181+Y181+Z181+AA181+AB181=0,IF(K181=S181,1,0),0) -> 0 | AD181: =IF(T181+U181+V181+W181+X181+Y181+Z181+AA181+AB181+AC181=0,IF(L181=S181,1,0),0) -> 0 | AE181: =IF(T181+U181+V181+W181+X181+Y181+Z181+AA181+AB181+AC181+AD181=0,IF(M181=S181,1,0),0) -> 0 | AF181: =IF(T181+U181+V181+W181+X181+Y181+Z181+AA181+AB181+AC181+AD181+AE181=0,IF(N181=S181,1,0),0) -> 0 | AG181: =IF(T181+U181+V181+W181+X181+Y181+Z181+AA181+AB181+AC181+AD181+AE181+AF181=0,IF(O181=S181,1,0),0) -> 0 | AH181: =IF(T181+U181+V181+W181+X181+Y181+Z181+AA181+AB181+AC181+AD181+AE181+AF181+AG181=0,IF(P181=S181,1,0),0) -> 0 | AI181: =IF(T181+U181+V181+W181+X181+Y181+Z181+AA181+AB181+AC181+AD181+AE181+AF181+AG181+AH181=0,IF(Q181=S181,1,0),0) -> 0 | AJ181: =IF(T181+U181+V181+W181+X181+Y181+Z181+AA181+AB181+AC181+AD181+AE181+AF181+AG181+AH181+AI181=0,IF(R181=S181,1,0),0) -> 0 | AK181: =T181+AK180 -> 76 | AL181: =U181+AL180 -> 89 | AM181: =V181+AM180 -> 0 | AN181: =W181+AN180 -> 0 | AO181: =X181+AO180 -> 0 | AP181: =Y181+AP180 -> 0 | AQ181: =Z181+AQ180 -> 0 | AR181: =AA181+AR180 -> 0 | ... BA181: =AJ181+BA180 -> 0 | BB181: =INDEX($T$14:$AJ$15,1,MATCH(1,T181:BA181,0)) -> Liste 2
A182: TOTAL | AK182: =AK181 -> 76 | AL182: =AL181 -> 89 | AM182: =AM181 -> 0 | AN182: =AN181 -> 0 | AO182: =AO181 -> 0 | AP182: =AP181 -> 0 | AQ182: =AQ181 -> 0 | AR182: =AR181 -> 0 | ... BA182: =BA181 -> 0
AK183: =IF(ISBLANK(B$10),"",B$10) -> Liste 1 | AL183: =IF(ISBLANK(C$10),"",C$10) -> Liste 2 | AM183: =IF(ISBLANK(D$10),"",D$10) -> Liste 3 | AN183: =IF(ISBLANK(E$10),"",E$10) -> Liste 4 | AO183: =IF(ISBLANK(F$10),"",F$10) -> Liste 5 | AP183: =IF(ISBLANK(G$10),"",G$10) -> Liste 6 | AQ183: =IF(ISBLANK(H$10),"",H$10) -> Liste 7 | AR183: =IF(ISBLANK(I$10),"",I$10) -> Liste 8 | ... BA183: =IF(ISBLANK(R$10),"",R$10) -> Liste 17
